<!-- Copyright 2021 DeepMind Technologies Limited

     Licensed under the Apache License, Version 2.0 (the "License");
     you may not use this file except in compliance with the License.
     You may obtain a copy of the License at

         http://www.apache.org/licenses/LICENSE-2.0

     Unless required by applicable law or agreed to in writing, software
     distributed under the License is distributed on an "AS IS" BASIS,
     WITHOUT WARRANTIES OR CONDITIONS OF ANY KIND, either express or implied.
     See the License for the specific language governing permissions and
     limitations under the License.
-->

<mujoco model="Humanoid">
    <option timestep="0.005" iterations="1" ls_iterations="4" solver="Newton" cone="pyramidal" impratio="100">
      <flag eulerdamp="disable"/>
    </option>
  
    <visual>
      <map force="0.1" zfar="30"/>
      <rgba haze="0.15 0.25 0.35 1"/>
      <global offwidth="2560" offheight="1440" elevation="-20" azimuth="120"/>
    </visual>
  
    <statistic center="0 0 0.7"/>
  
    <asset>
      <texture type="skybox" builtin="gradient" rgb1=".3 .5 .7" rgb2="0 0 0" width="32" height="512"/>
      <texture name="body" type="cube" builtin="flat" mark="cross" width="128" height="128" rgb1="0.8 0.6 0.4" rgb2="0.8 0.6 0.4" markrgb="1 1 1" random="0.01"/>
      <material name="body" texture="body" texuniform="true" rgba="0.8 0.6 .4 1"/>
      <texture name="grid" type="2d" builtin="checker" width="512" height="512" rgb1=".1 .2 .3" rgb2=".2 .3 .4"/>
      <material name="grid" texture="grid" texrepeat="1 1" texuniform="true" reflectance=".2"/>
    </asset>
  
    <default>
      <motor ctrlrange="-1 1" ctrllimited="true"/>
      <default class="body">
  
        <!-- geoms -->
        <!-- TODO(robotics-simulation): support condim=1 for humanoid capsules. -->
        <geom type="capsule" condim="3" friction=".7" solimp=".9 .99 .003" solref=".015 1" material="body" contype="0" conaffinity="0"/>
        <default class="thigh">
          <geom size=".06"/>
        </default>
        <default class="shin">
          <geom fromto="0 0 0 0 0 -.3"  size=".049"/>
        </default>
        <default class="foot">
          <geom size=".027"/>
          <default class="foot1">
            <geom fromto="-.07 -.01 0 .14 -.03 0"/>
          </default>
          <default class="foot2">
            <geom fromto="-.07 .01 0 .14  .03 0"/>
          </default>
        </default>
        <default class="arm_upper">
          <geom size=".04"/>
        </default>
        <default class="arm_lower">
          <geom size=".031"/>
        </default>
        <default class="hand">
          <geom type="sphere" size=".04"/>
        </default>
  
        <!-- joints -->
        <joint type="hinge" damping=".2" stiffness="1" armature=".01" limited="true" solimplimit="0 .99 .01"/>
        <default class="joint_big">
          <joint damping="5" stiffness="10"/>
          <default class="hip_x">
            <joint range="-30 10"/>
          </default>
          <default class="hip_z">
            <joint range="-60 35"/>
          </default>
          <default class="hip_y">
            <joint axis="0 1 0" range="-150 20"/>
          </default>
          <default class="joint_big_stiff">
            <joint stiffness="20"/>
          </default>
        </default>
        <default class="knee">
          <joint pos="0 0 .02" axis="0 -1 0" range="-160 2"/>
        </default>
        <default class="ankle">
          <joint range="-50 50"/>
          <default class="ankle_y">
            <joint pos="0 0 .08" axis="0 1 0" stiffness="6"/>
          </default>
          <default class="ankle_x">
            <joint pos="0 0 .04" stiffness="3"/>
          </default>
        </default>
        <default class="shoulder">
          <joint range="-85 60"/>
        </default>
        <default class="elbow">
          <joint range="-100 50" stiffness="0"/>
        </default>
      </default>
    </default>
  
    <worldbody>
      <geom conaffinity="1" condim="3" friction="1 .1 .1" material="grid" name="floor" pos="0 0 0" size="20 20 0.125" type="plane"/>
      <camera name="close_profile" mode="trackcom" pos="5 -5 5" xyaxes="1 1 0 -1 1 2"/>
      <camera name="track" mode="trackcom" pos="0 4 0" xyaxes="1 0 0 0 0 1"/>
      <replicate count="2" euler="0 0 180" sep="-">
<light name="spotlight" mode="targetbodycom" target="torso" diffuse=".8 .8 .8" specular="0.3 0.3 0.3" pos="0 -6 4" cutoff="30"/>
        <!-- <geom condim="3" material="MatPlane" name="floor" pos="0 0 0" size="10 10 0.125" type="plane"/>-->
        <body name="torso" pos="0 0 1.4">
        <light name="top" pos="0 0 2" mode="trackcom"/>
            <joint armature="0" damping="0" limited="false" name="root" pos="0 0 0" stiffness="0" type="free"/>
            <geom fromto="0 -.07 0 0 .07 0" name="torso1" size="0.07" type="capsule"/>
            <geom name="head" pos="0 0 .19" size=".09" type="sphere" user="258"/>
            <geom fromto="-.01 -.06 -.12 -.01 .06 -.12" name="uwaist" size="0.06" type="capsule"/>
            <body name="lwaist" pos="-.01 0 -0.260" quat="1.000 0 -0.002 0">
                <geom fromto="0 -.06 0 0 .06 0" name="lwaist" size="0.06" type="capsule"/>
                <joint armature="0.02" axis="0 0 1" damping="5" name="abdomen_z" pos="0 0 0.065" range="-45 45" stiffness="20" type="hinge"/>
                <joint armature="0.02" axis="0 1 0" damping="5" name="abdomen_y" pos="0 0 0.065" range="-75 30" stiffness="10" type="hinge"/>
                <body name="pelvis" pos="0 0 -0.165" quat="1.000 0 -0.002 0">
                    <joint armature="0.02" axis="1 0 0" damping="5" name="abdomen_x" pos="0 0 0.1" range="-35 35" stiffness="10" type="hinge"/>
                    <geom fromto="-.02 -.07 0 -.02 .07 0" name="butt" size="0.09" type="capsule"/>
                    <body name="right_thigh" pos="0 -0.1 -0.04">
                        <joint armature="0.01" axis="1 0 0" damping="5" name="right_hip_x" pos="0 0 0" range="-25 5" stiffness="10" type="hinge"/>
                        <joint armature="0.01" axis="0 0 1" damping="5" name="right_hip_z" pos="0 0 0" range="-60 35" stiffness="10" type="hinge"/>
                        <joint armature="0.0080" axis="0 1 0" damping="5" name="right_hip_y" pos="0 0 0" range="-110 20" stiffness="20" type="hinge"/>
                        <geom fromto="0 0 0 0 0.01 -.34" name="right_thigh1" size="0.06" type="capsule"/>
                        <body name="right_shin" pos="0 0.01 -0.403">
                            <joint armature="0.0060" axis="0 -1 0" name="right_knee" pos="0 0 .02" range="-160 -2" type="hinge"/>
                            <geom fromto="0 0 0 0 0 -.3" name="right_shin1" size="0.049" type="capsule"/>
                            <body name="right_foot" pos="0 0 -0.45">
                                <geom contype="1" name="right_foot" pos="0 0 0.1" size="0.075" type="sphere" user="0"/>
                            </body>
                        </body>
                    </body>
                    <body name="left_thigh" pos="0 0.1 -0.04">
                        <joint armature="0.01" axis="-1 0 0" damping="5" name="left_hip_x" pos="0 0 0" range="-25 5" stiffness="10" type="hinge"/>
                        <joint armature="0.01" axis="0 0 -1" damping="5" name="left_hip_z" pos="0 0 0" range="-60 35" stiffness="10" type="hinge"/>
                        <joint armature="0.01" axis="0 1 0" damping="5" name="left_hip_y" pos="0 0 0" range="-110 20" stiffness="20" type="hinge"/>
                        <geom fromto="0 0 0 0 -0.01 -.34" name="left_thigh1" size="0.06" type="capsule"/>
                        <body name="left_shin" pos="0 -0.01 -0.403">
                            <joint armature="0.0060" axis="0 -1 0" name="left_knee" pos="0 0 .02" range="-160 -2" stiffness="1" type="hinge"/>
                            <geom fromto="0 0 0 0 0 -.3" name="left_shin1" size="0.049" type="capsule"/>
                            <body name="left_foot" pos="0 0 -0.45">
                                <geom contype="1" name="left_foot" type="sphere" size="0.075" pos="0 0 0.1" user="0" />
                            </body>
                        </body>
                    </body>
                </body>
            </body>
            <body name="right_upper_arm" pos="0 -0.17 0.06">
                <joint armature="0.0068" axis="2 1 1" name="right_shoulder1" pos="0 0 0" range="-85 60" stiffness="1" type="hinge"/>
                <joint armature="0.0051" axis="0 -1 1" name="right_shoulder2" pos="0 0 0" range="-85 60" stiffness="1" type="hinge"/>
                <geom fromto="0 0 0 .16 -.16 -.16" name="right_uarm1" size="0.04 0.16" type="capsule"/>
                <body name="right_lower_arm" pos=".18 -.18 -.18">
                    <joint armature="0.0028" axis="0 -1 1" name="right_elbow" pos="0 0 0" range="-90 50" stiffness="0" type="hinge"/>
                    <geom fromto="0.01 0.01 0.01 .17 .17 .17" name="right_larm" size="0.031" type="capsule"/>
                    <geom name="right_hand" pos=".18 .18 .18" size="0.04" type="sphere"/>
                    <camera pos="0 0 0"/>
                </body>
            </body>
            <body name="left_upper_arm" pos="0 0.17 0.06">
                <joint armature="0.0068" axis="2 -1 1" name="left_shoulder1" pos="0 0 0" range="-60 85" stiffness="1" type="hinge"/>
                <joint armature="0.0051" axis="0 1 1" name="left_shoulder2" pos="0 0 0" range="-60 85" stiffness="1" type="hinge"/>
                <geom fromto="0 0 0 .16 .16 -.16" name="left_uarm1" size="0.04 0.16" type="capsule"/>
                <body name="left_lower_arm" pos=".18 .18 -.18">
                    <joint armature="0.0028" axis="0 -1 -1" name="left_elbow" pos="0 0 0" range="-90 50" stiffness="0" type="hinge"/>
                    <geom fromto="0.01 -0.01 0.01 .17 -.17 .17" name="left_larm" size="0.031" type="capsule"/>
                    <geom name="left_hand" pos=".18 -.18 .18" size="0.04" type="sphere"/>
                </body>
            </body>
        </body>
      </replicate>
    </worldbody>
  
  
  </mujoco>